<?xml version="1.0"?>
<robot name="roboarm" >
	<link name="base_link">
		<visual>
			<geometry>
				<box size="2.5 1.5 0.1" />
			</geometry>
			<material name="blue">
				<color rgba="0 0 1 1"/>
			</material>
		</visual>
	</link>
	
	<link name="forearm1">
		<visual>
			<origin xyz="0 0 0" rpy="0 0 0"/>
			<geometry>
				<box size="2.5 1.5 0.1" />
			</geometry>
			<material name="blue">
				<color rgba="0 0 1 1"/>
			</material>
		</visual>
	</link>
	
	<link name="forearm2">
		<visual>
			<origin xyz="0 0 0" rpy="0 0 0"/>
			<geometry>
				<box size="2.5 1.5 0.1" />
			</geometry>
			<material name="blue">
				<color rgba="0 0 1 1"/>
			</material>
		</visual>
	</link>
	
	<link name="forearm3">
		<visual>
			<origin xyz="0 0 0" rpy="0 0 0"/>
			<geometry>
				<box size="2.5 1.5 0.1" />
			</geometry>
			<material name="blue">
				<color rgba="0 0 1 1"/>
			</material>
		</visual>
	</link>
	
	<link name="palm">
		<visual>
			<origin xyz="0 0 0" rpy="0 0 0"/>
			<geometry>
				<box size="2.5 1.5 0.1" />
			</geometry>
			<material name="blue">
				<color rgba="0 0 1 1"/>
			</material>
		</visual>
	</link>
	
	
	
	<joint name="joint1" type="continuous">
		<parent link="base_link"/>
		<child link="forearm1"/>
		<origin xyz="0 0 0" rpy="0 0 0"/>
		<axis xyz="0 0 1"/>
	</joint>
	
	<joint name="elbow1" type="revolute">
		<parent link="forearm1"/>
		<child link="forearm2"/>
		<origin xyz="0 0 0.3" rpy="0 0 0"/>
		<axis xyz="0 0 1"/>
		<limit lower="-3.14" upper="3.14" effort="100.0" velocity="0.5"/>
	</joint>
	
	<joint name="elbow2" type="revolute">
		<parent link="forearm2"/>
		<child link="forearm3"/>
		<origin xyz="0 0 0.3" rpy="0 0 0"/>
		<axis xyz="0 0 1"/>
		<limit lower="-3.14" upper="3.14" effort="100.0" velocity="0.5"/>
	</joint>
	
	<joint name="wrist" type="revolute">
		<parent link="forearm3"/>
		<child link="palm"/>
		<origin xyz="0 0 0.3" rpy="0 0 0"/>
		<axis xyz="0 0 1"/>
		<limit lower="-3.14" upper="3.14" effort="100.0" velocity="0.5"/>
	</joint>
	
</robot>