<?xml version="1.0"?>
<robot name="roboarm" xmlns:xacro="http://www.ros.org/wiki/xacro">
	
	<link name="world"></link>

	<link name="base_link">
		<visual>
			<origin xyz="0 0 0" rpy="0 0 0"/>
			<geometry>
				<box size="1 1 0.1" />
			</geometry>
			<material name="blue">
				<color rgba="0 0 1 1"/>
			</material>
		</visual>
	</link>
	
	<link name="forearm1">
		<visual>
			<origin xyz="0 0 0" rpy="0 0 0"/>
			<geometry>
				<box size="0.25 0.25 1" />
			</geometry>
			<material name="blue">
				<color rgba="0 0 1 1"/>
			</material>
		</visual>
	</link>
	
	<link name="forearm2">
		<visual>
			<origin xyz="0 0 0.5" rpy="0 0 0"/>
			<geometry>
				<box size="0.25 0.25 1" />
			</geometry>
			<material name="blue">
				<color rgba="0 0 1 1"/>
			</material>
		</visual>
	</link>
	
	<link name="forearm3">
		<visual>
			<origin xyz="0 0 0.5" rpy="0 0 0"/>
			<geometry>
				<box size="0.25 0.25 1" />
			</geometry>
			<material name="blue">
				<color rgba="0 0 1 1"/>
			</material>
		</visual>
	</link>
	
	<link name="palm">
		<visual>
			<origin xyz="0 0 0.25" rpy="0 0 0"/>
			<geometry>
				<box size="0.1 0.5 0.5" />
			</geometry>
			<material name="blue">
				<color rgba="0 0 1 1"/>
			</material>
		</visual>
	</link>



	<joint name="base_joint" type="fixed">
		<origin xyz="1.5 1.0 0" rpy="0 0 0"/>
		<parent link="world"/>
		<child link="base_link"/>
	</joint>
	
	<joint name="rotation" type="continuous">
		<parent link="base_link"/>
		<child link="forearm1"/>
		<origin xyz="0 0 0.5" rpy="0 0 0"/>
		<axis xyz="0 0 1"/>
	</joint>
	
	<joint name="elbow1" type="continuous">
		<parent link="forearm1"/>
		<child link="forearm2"/>
		<origin xyz="0 0 0.5" rpy="0 0 0"/>
		<axis xyz="0 1 0"/>
	</joint>
	
	<joint name="elbow2" type="continuous">
		<parent link="forearm2"/>
		<child link="forearm3"/>
		<origin xyz="0 0 1" rpy="0 0 0"/>
		<axis xyz="0 1 0"/>
	</joint>
	
	<joint name="wrist" type="continuous">
		<parent link="forearm3"/>
		<child link="palm"/>
		<origin xyz="0 0 1" rpy="0 0 0"/>
		<axis xyz="1 0 0"/>
	</joint>
	
	
	
</robot>